Traceback (most recent call last):
  File "/opt/hostedtoolcache/Python/3.9.7/x64/lib/python3.9/site-packages/jupyter_cache/executors/utils.py", line 51, in single_nb_execution
    executenb(
  File "/opt/hostedtoolcache/Python/3.9.7/x64/lib/python3.9/site-packages/nbclient/client.py", line 1117, in execute
    return NotebookClient(nb=nb, resources=resources, km=km, **kwargs).execute()
  File "/opt/hostedtoolcache/Python/3.9.7/x64/lib/python3.9/site-packages/nbclient/util.py", line 78, in wrapped
    return just_run(coro(*args, **kwargs))
  File "/opt/hostedtoolcache/Python/3.9.7/x64/lib/python3.9/site-packages/nbclient/util.py", line 57, in just_run
    return loop.run_until_complete(coro)
  File "/opt/hostedtoolcache/Python/3.9.7/x64/lib/python3.9/asyncio/base_events.py", line 642, in run_until_complete
    return future.result()
  File "/opt/hostedtoolcache/Python/3.9.7/x64/lib/python3.9/site-packages/nbclient/client.py", line 558, in async_execute
    await self.async_execute_cell(
  File "/opt/hostedtoolcache/Python/3.9.7/x64/lib/python3.9/site-packages/nbclient/client.py", line 862, in async_execute_cell
    self._check_raise_for_error(cell, exec_reply)
  File "/opt/hostedtoolcache/Python/3.9.7/x64/lib/python3.9/site-packages/nbclient/client.py", line 765, in _check_raise_for_error
    raise CellExecutionError.from_cell_and_msg(cell, exec_reply_content)
nbclient.exceptions.CellExecutionError: An error occurred while executing the following cell:
------------------
data1 #=
data2 #=
p.check_p03(data1,data2)
------------------

[0;31m---------------------------------------------------------------------------[0m
[0;31mUnboundLocalError[0m                         Traceback (most recent call last)
[0;32m/tmp/ipykernel_1617/2060265219.py[0m in [0;36m<module>[0;34m[0m
[1;32m      1[0m [0mdata1[0m [0;31m#=[0m[0;34m[0m[0;34m[0m[0m
[1;32m      2[0m [0mdata2[0m [0;31m#=[0m[0;34m[0m[0;34m[0m[0m
[0;32m----> 3[0;31m [0mp[0m[0;34m.[0m[0mcheck_p03[0m[0;34m([0m[0mdata1[0m[0;34m,[0m[0mdata2[0m[0;34m)[0m[0;34m[0m[0;34m[0m[0m
[0m
[0;32m~/work/sensors_and_data/sensors_and_data/ME3263-Lab_00/check_lab00.py[0m in [0;36mcheck_p03[0;34m(data1, data2)[0m
[1;32m     45[0m     [0;32melse[0m[0;34m:[0m[0;34m[0m[0;34m[0m[0m
[1;32m     46[0m         [0mprint[0m[0;34m([0m[0;34m'Whoops, try again'[0m[0;34m)[0m[0;34m[0m[0;34m[0m[0m
[0;32m---> 47[0;31m         [0;32mreturn[0m [0mpoints[0m[0;34m[0m[0;34m[0m[0m
[0m[1;32m     48[0m [0;34m[0m[0m
[1;32m     49[0m [0;32mif[0m [0m__name__[0m[0;34m==[0m[0;34m'__main__'[0m[0;34m:[0m[0;34m[0m[0;34m[0m[0m

[0;31mUnboundLocalError[0m: local variable 'points' referenced before assignment
UnboundLocalError: local variable 'points' referenced before assignment

